Traceback (most recent call last):
  File "/home/vkeller/.local/pipx/venvs/jupyter-book/lib/python3.11/site-packages/jupyter_core/utils/__init__.py", line 154, in wrapped
    asyncio.get_running_loop()
RuntimeError: no running event loop

During handling of the above exception, another exception occurred:

Traceback (most recent call last):
  File "/home/vkeller/.local/pipx/venvs/jupyter-book/lib/python3.11/site-packages/jupyter_cache/executors/utils.py", line 58, in single_nb_execution
    executenb(
  File "/home/vkeller/.local/pipx/venvs/jupyter-book/lib/python3.11/site-packages/nbclient/client.py", line 1319, in execute
    return NotebookClient(nb=nb, resources=resources, km=km, **kwargs).execute()
           ^^^^^^^^^^^^^^^^^^^^^^^^^^^^^^^^^^^^^^^^^^^^^^^^^^^^^^^^^^^^^^^^^^^^^
  File "/home/vkeller/.local/pipx/venvs/jupyter-book/lib/python3.11/site-packages/jupyter_core/utils/__init__.py", line 158, in wrapped
    return loop.run_until_complete(inner)
           ^^^^^^^^^^^^^^^^^^^^^^^^^^^^^^
  File "/usr/lib/python3.11/asyncio/base_events.py", line 653, in run_until_complete
    return future.result()
           ^^^^^^^^^^^^^^^
  File "/home/vkeller/.local/pipx/venvs/jupyter-book/lib/python3.11/site-packages/nbclient/client.py", line 709, in async_execute
    await self.async_execute_cell(
  File "/home/vkeller/.local/pipx/venvs/jupyter-book/lib/python3.11/site-packages/nbclient/client.py", line 1062, in async_execute_cell
    await self._check_raise_for_error(cell, cell_index, exec_reply)
  File "/home/vkeller/.local/pipx/venvs/jupyter-book/lib/python3.11/site-packages/nbclient/client.py", line 918, in _check_raise_for_error
    raise CellExecutionError.from_cell_and_msg(cell, exec_reply_content)
nbclient.exceptions.CellExecutionError: An error occurred while executing the following cell:
------------------
# Author: Gael Varoquaux <gael dot varoquaux at normalesup dot org>
# License: BSD 3 clause

# Standard scientific Python imports
import matplotlib.pyplot as plt

# Import datasets, classifiers and performance metrics
from sklearn import datasets, metrics, svm
from sklearn.model_selection import train_test_split
------------------


[31m---------------------------------------------------------------------------[39m
[31mModuleNotFoundError[39m                       Traceback (most recent call last)
[36mCell[39m[36m [39m[32mIn[1][39m[32m, line 5[39m
[32m      1[39m [38;5;66;03m# Author: Gael Varoquaux <gael dot varoquaux at normalesup dot org>[39;00m
[32m      2[39m [38;5;66;03m# License: BSD 3 clause[39;00m
[32m      3[39m 
[32m      4[39m [38;5;66;03m# Standard scientific Python imports[39;00m
[32m----> [39m[32m5[39m [38;5;28;01mimport[39;00m[38;5;250m [39m[34;01mmatplotlib[39;00m[34;01m.[39;00m[34;01mpyplot[39;00m[38;5;250m [39m[38;5;28;01mas[39;00m[38;5;250m [39m[34;01mplt[39;00m
[32m      7[39m [38;5;66;03m# Import datasets, classifiers and performance metrics[39;00m
[32m      8[39m [38;5;28;01mfrom[39;00m[38;5;250m [39m[34;01msklearn[39;00m[38;5;250m [39m[38;5;28;01mimport[39;00m datasets, metrics, svm

[31mModuleNotFoundError[39m: No module named 'matplotlib'

